<!--デフォルトの記述-->

<%# if resource.errors.any? %>
  <!--<div id="error_explanation">-->
<!--    <h2>-->
<!--      <%#= I18n.t("errors.messages.not_saved",-->
<!--                 count: resource.errors.count,-->
<!--                 resource: resource.class.model_name.human.downcase)-->
<!--       %>-->
<!--    </h2>-->
<!--    <ul>-->
<!--      <%# resource.errors.full_messages.each do |message| %>-->
<!--        <li><%#= message %></li>-->
<!--      <%# end %>-->
<!--    </ul>-->
<!--  </div>-->
<!--<%# end %>-->

<!--編集した記述-->
<% if obj.errors.any? %>
  <h3><%= obj.errors.count %> 件のエラーが発生しました。</h3>
  <ul>
    <% obj.errors.full_messages.each do |message| %>
      <li><%= message %></li>
    <% end %>
  </ul>
<% end %>



